Workbook

Sheet Constituents2021
A1: =_xll.Thomson.Reuters.AFOSpreadsheetFormulas.DSGRID("LDJSTOXX0121","ISIN","Latest Value","","","RowHeader=true;ColHeader=true;DispSeriesDescription=true;DispDatatypeDescription=true;AutoRefresh=false","") -> #NAME? | B1: ISIN CODE
A2: 960338 | B2: GB00B1YW4409
A3: 997863 | B3: DK0010244508
A4: 685120 | B4: IT0001233417
A5: 31938W | B5: SE0011337708
A6: 749352 | B6: NL0000852564
A7: 922924 | B7: CH0012221716
A8: 8721AT | B8: NL0011540547
A9: 741112 | B9: ES0125220311
A10: 929363 | B10: FR0000120404
A11: 755087 | B11: BE0003764785
A12: 539621 | B12: ES0167050915
A13: 257663 | B13: SE0014781795
A14: 992838 | B14: CH0012138605
A15: 9441K0 | B15: NO0010844038
A16: 870874 | B16: DE000A1EWWW0
A17: 9746D6 | B17: LU1250154413
A18: 29549F | B18: GB00B02J6398
A19: 36066K | B19: FR0010340141
A20: 9307KF | B20: NL0012969182
A21: 41293M | B21: BE0003851681
A22: 922956 | B22: BMG0112X1056
A23: 89240U | B23: ES0105046009
A24: 749488 | B24: SE0005999836
A25: 929303 | B25: BE0974264930
A26: 916642 | B26: NL0011794037
A27: 923295 | B27: FR0000120073
A28: 289361 | B28: NL0000235190
A29: 51429U | B29: NO0010345853
A30: 912643 | B30: NL0013267909
A31: 94405Z | B31: CH0432492467
A32: 25522V | B32: SE0000695876
A33: 9839J3 | B33: LU2237380790
A34: 866033 | B34: DE0008404005
A35: 276819 | B35: CH0008837566
A36: 682858 | B36: FR0010220475
A37: 50367Q | B37: DE000A0LD2U1
A38: 692445 | B38: FR0000071946
A39: 69265H | B39: ES0109067019
A40: 307640 | B40: DK0060946788
...

Sheet Constituents_Identifiers
A1: =_xll.Thomson.Reuters.AFOSpreadsheetFormulas.DSGRID("LDJSTOXX0121","ISIN;NAME","Latest Value","","","RowHeader=true;ColHeader=true;DispSeriesDescription=true;DispDatatypeDescription=true;AutoRefresh=false","") -> #NAME? | B1: ISIN CODE | C1: NAME
A2: 960338 | B2: GB00B1YW4409 | C2: 3I GROUP
A3: 997863 | B3: DK0010244508 | C3: A P MOLLER MAERSK B
A4: 685120 | B4: IT0001233417 | C4: A2A
A5: 31938W | B5: SE0011337708 | C5: AAK
A6: 749352 | B6: NL0000852564 | C6: AALBERTS
A7: 922924 | B7: CH0012221716 | C7: ABB LTD N
A8: 8721AT | B8: NL0011540547 | C8: ABN AMRO BANK
A9: 741112 | B9: ES0125220311 | C9: ACCIONA
A10: 929363 | B10: FR0000120404 | C10: ACCOR
A11: 755087 | B11: BE0003764785 | C11: ACKERMANS & VAN HAAREN
A12: 539621 | B12: ES0167050915 | C12: ACS ACTIV.CONSTR.Y SERV.
A13: 257663 | B13: SE0014781795 | C13: ADDTECH B
A14: 992838 | B14: CH0012138605 | C14: ADECCO GROUP
A15: 9441K0 | B15: NO0010844038 | C15: ADEVINTA
A16: 870874 | B16: DE000A1EWWW0 | C16: ADIDAS (XET)
A17: 9746D6 | B17: LU1250154413 | C17: ADLER GROUP (XET)
A18: 29549F | B18: GB00B02J6398 | C18: ADMIRAL GROUP
A19: 36066K | B19: FR0010340141 | C19: ADP
A20: 9307KF | B20: NL0012969182 | C20: ADYEN
A21: 41293M | B21: BE0003851681 | C21: AEDIFICA
A22: 922956 | B22: BMG0112X1056 | C22: AEGON
A23: 89240U | B23: ES0105046009 | C23: AENA SME
A24: 749488 | B24: SE0005999836 | C24: AFRY
A25: 929303 | B25: BE0974264930 | C25: AGEAS (EX-FORTIS)
A26: 916642 | B26: NL0011794037 | C26: KONINKLIJKE AHOLD DELHAIZE
A27: 923295 | B27: FR0000120073 | C27: L AIR LQE.SC.ANYME. POUR L ETUDE ET L EPXTN.
A28: 289361 | B28: NL0000235190 | C28: AIRBUS
A29: 51429U | B29: NO0010345853 | C29: AKER BP
A30: 912643 | B30: NL0013267909 | C30: AKZO NOBEL
A31: 94405Z | B31: CH0432492467 | C31: ALCON (SWX) ORD SHS
A32: 25522V | B32: SE0000695876 | C32: ALFA LAVAL
A33: 9839J3 | B33: LU2237380790 | C33: ALLEGRO
A34: 866033 | B34: DE0008404005 | C34: ALLIANZ (XET)
A35: 276819 | B35: CH0008837566 | C35: ALLREAL HOLDING
A36: 682858 | B36: FR0010220475 | C36: ALSTOM
A37: 50367Q | B37: DE000A0LD2U1 | C37: ALSTRIA OFFICE REIT(XET)
A38: 692445 | B38: FR0000071946 | C38: ALTEN
A39: 69265H | B39: ES0109067019 | C39: AMADEUS IT GROUP
A40: 307640 | B40: DK0060946788 | C40: AMBU B
...

Sheet FinancialData
A1: Name | B1: 2021 | C1: 2022 | D1: 2023
A2: 3I GROUP PLC - COMMON SHAREHOLDERS' EQUITY | B2: 9164000 | C2: 12754000 | D2: 16844000
A3: 3I GROUP PLC - TOTAL ASSETS | B3: 10333000 | C3: 13947000 | D3: 17819000
A4: #ERROR | B4: $$ER: 4540,NO DATA VALUES FOUND
A5: 3I GROUP PLC - TOTAL DEBT | B5: 992000 | C5: 989000 | D5: 785000
A6: 3I GROUP PLC - TOTAL LIABILITIES | B6: 1169000 | C6: 1193000 | D6: 975000
A7: #ERROR | B7: $$ER: 4540,NO DATA VALUES FOUND
A8: #ERROR | B8: $$ER: 4540,NO DATA VALUES FOUND
A9: 3I GROUP PLC - NET INCOME - BASIC | B9: 1855000 | C9: 4013000 | D9: 4573000
A10: 3I GROUP PLC - NET INCOME AVAILABLE TO COMMON | B10: 1855000 | C10: 4013000 | D10: 4573000
A11: 3I GROUP PLC - NET INCOME (U.S.$) | B11: 2555096 | C11: 5273323 | D11: 5638738
A12: 3I GROUP PLC - NET SALES OR REVENUES | B12: 739000 | C12: 2411000 | D12: 2758000
A13: 3I GROUP PLC - COST OF GOODS SOLD (EXCL DEP) | B13: 6000 | C13: 46000 | D13: 38000
A14: 3I GROUP PLC - EARNINGS BEF INTEREST & TAXES | B14: 1903000 | C14: 4071000 | D14: 4629000
A15: 3I GROUP PLC - EBIT & DEPRECIATION | B15: 1910000 | C15: 4078000 | D15: 4635000
A16: 3I GROUP PLC - INTEREST EXPENSE - TOTAL | B16: 48000 | C16: 53000 | D16: 54000
A17: 3I GROUP PLC - CASH - GENERIC | B17: 226000 | C17: 222000 | D17: 210000
A18: #ERROR | B18: $$ER: 4540,NO DATA VALUES FOUND
A19: #ERROR | B19: $$ER: 4540,NO DATA VALUES FOUND
A20: 3I GROUP PLC - TOTAL INVENTORIES | B20: 0 | C20: 0 | D20: 0
A21: #ERROR | B21: $$ER: 4540,NO DATA VALUES FOUND
A22: 3I GROUP PLC - CASH FLOW PER SHARE | B22: -0.688 | C22: 0.484 | D22: 0.511
A23: #ERROR | B23: $$ER: 4540,NO DATA VALUES FOUND
A24: #ERROR | B24: $$ER: 4540,NO DATA VALUES FOUND
A25: #ERROR | B25: $$ER: 4540,NO DATA VALUES FOUND
A26: #ERROR | B26: $$ER: 4540,NO DATA VALUES FOUND
A27: 3I GROUP PLC - LONG TERM DEBT | B27: 988000 | C27: 784000 | D27: 780000
A28: 3I GROUP PLC - SHORT TERM DEBT & CURRENT PORT | B28: 4000 | C28: 205000 | D28: 5000
A29: 3I GROUP PLC - SALARIES & BENEFITS EXPENSES | B29: 76000 | C29: 89000 | D29: 97000
A30: 3I GROUP PLC - TOTAL INVESTMENTS | B30: 5026000 | C30: 6649000 | D30: 9591000
A31: 3I GROUP PLC - TOTAL CAPITAL | B31: 10152000 | C31: 13538000 | D31: 17624000
A32: 3I GROUP PLC - TOTAL SHAREHOLDERS EQUITY | B32: 9164000 | C32: 12754000 | D32: 16844000
A33: 3I GROUP PLC - GROSS PROFIT MARGIN | B33: 98.24 | C33: 97.8 | D33: 98.4
A34: 3I GROUP PLC - GROSS INCOME | B34: 726000 | C34: 2358000 | D34: 2714000
A35: 3I GROUP PLC - RETAINED EARNINGS | B35: 7726000 | C35: 11352000 | D35: 15445000
A36: 3I GROUP PLC - RECEIVABLES(NET) | B36: 19000 | C36: 61000 | D36: 44000
A37: 3I GROUP PLC - CASH - GENERIC | B37: 226000 | C37: 222000 | D37: 210000
A38: 3I GROUP PLC - NUMBER OF SHARES | B38: 973136 | C38: 973211 | D38: 973289
A39: #ERROR | B39: $$ER: E100,INVALID CODE OR EXPRESSION ENTERED
A40: #ERROR | B40: $$ER: E100,INVALID CODE OR EXPRESSION ENTERED
...

Sheet IndustryClassifier2021
A1: ISIN | B1: INDUSTRY GROUP | C1: SIC CODE 1 | D1: SIC CODE 2 | E1: SIC CODE 3 | F1: INDM
A2: GB00B1YW4409 | B2: 109 | C2: 6799 | F2: =INDEX(Industries!$D$2:$D$473,MATCH(B2,Industries!$B$2:$B$473,0)) -> Investment Trusts
A3: DK0010244508 | B3: 99 | C3: 4412 | D3: 4491 | E3: 1389 | F3: =INDEX(Industries!$D$2:$D$473,MATCH(B3,Industries!$B$2:$B$473,0)) -> Marine Transportation
A4: IT0001233417 | B4: 169 | C4: 4911 | D4: 4924 | E4: 4941 | F4: =INDEX(Industries!$D$2:$D$473,MATCH(B4,Industries!$B$2:$B$473,0)) -> Conv. Electricity
A5: SE0011337708 | B5: 71 | C5: 2079 | D5: 2869 | E5: 2035 | F5: =INDEX(Industries!$D$2:$D$473,MATCH(B5,Industries!$B$2:$B$473,0)) -> Food Products
A6: NL0000852564 | B6: 213 | C6: 3498 | D6: 3491 | E6: 3492 | F6: =INDEX(Industries!$D$2:$D$473,MATCH(B6,Industries!$B$2:$B$473,0)) -> Elec. Eq: Control
A7: CH0012221716 | B7: 258 | C7: 3613 | D7: 3612 | E7: 3823 | F7: =INDEX(Industries!$D$2:$D$473,MATCH(B7,Industries!$B$2:$B$473,0)) -> Electrical Components
A8: NL0011540547 | B8: 102 | C8: 6029 | D8: 6331 | E8: 6311 | F8: =INDEX(Industries!$D$2:$D$473,MATCH(B8,Industries!$B$2:$B$473,0)) -> Banks
A9: ES0125220311 | B9: 39 | C9: 1629 | D9: 8711 | E9: 1611 | F9: =INDEX(Industries!$D$2:$D$473,MATCH(B9,Industries!$B$2:$B$473,0)) -> Construction
A10: FR0000120404 | B10: 80 | C10: 7011 | D10: 6719 | F10: =INDEX(Industries!$D$2:$D$473,MATCH(B10,Industries!$B$2:$B$473,0)) -> Hotels & Motels
A11: BE0003764785 | B11: 216 | C11: 1629 | D11: 1541 | E11: 1623 | F11: =INDEX(Industries!$D$2:$D$473,MATCH(B11,Industries!$B$2:$B$473,0)) -> Eng. & Contract Svs
A12: ES0167050915 | B12: 39 | C12: 1611 | D12: 1623 | E12: 1541 | F12: =INDEX(Industries!$D$2:$D$473,MATCH(B12,Industries!$B$2:$B$473,0)) -> Construction
A13: SE0014781795 | B13: 258 | C13: 5084 | D13: 5063 | E13: 5065 | F13: =INDEX(Industries!$D$2:$D$473,MATCH(B13,Industries!$B$2:$B$473,0)) -> Electrical Components
A14: CH0012138605 | B14: 134 | C14: 7363 | D14: 8742 | E14: 7361 | F14: =INDEX(Industries!$D$2:$D$473,MATCH(B14,Industries!$B$2:$B$473,0)) -> Training, Emp. Agency
A15: NO0010844038 | B15: 156 | C15: 7375 | F15: =INDEX(Industries!$D$2:$D$473,MATCH(B15,Industries!$B$2:$B$473,0)) -> Consumer Svs: Misc.
A16: DE000A1EWWW0 | B16: 153 | C16: 3149 | D16: 2252 | E16: 2329 | F16: =INDEX(Industries!$D$2:$D$473,MATCH(B16,Industries!$B$2:$B$473,0)) -> Footwear
A17: LU1250154413 | B17: 112 | C17: 6513 | D17: 6531 | F17: =INDEX(Industries!$D$2:$D$473,MATCH(B17,Industries!$B$2:$B$473,0)) -> Real Estate Hold, Dev
A18: GB00B02J6398 | B18: 107 | C18: 6331 | D18: 6411 | E18: 6719 | F18: =INDEX(Industries!$D$2:$D$473,MATCH(B18,Industries!$B$2:$B$473,0)) -> Prop. & Casualty Ins.
A19: FR0010340141 | B19: 64 | C19: 4581 | D19: 7389 | F19: =INDEX(Industries!$D$2:$D$473,MATCH(B19,Industries!$B$2:$B$473,0)) -> Transport Services
A20: NL0012969182 | B20: 261 | C20: 7372 | F20: =INDEX(Industries!$D$2:$D$473,MATCH(B20,Industries!$B$2:$B$473,0)) -> Transaction Process
A21: BE0003851681 | B21: 222 | C21: 6513 | F21: =INDEX(Industries!$D$2:$D$473,MATCH(B21,Industries!$B$2:$B$473,0)) -> Health Care REITs
A22: BMG0112X1056 | B22: 106 | C22: 6311 | D22: 6324 | E22: 6331 | F22: =INDEX(Industries!$D$2:$D$473,MATCH(B22,Industries!$B$2:$B$473,0)) -> Life Insurance
A23: ES0105046009 | B23: 64 | C23: 4581 | F23: =INDEX(Industries!$D$2:$D$473,MATCH(B23,Industries!$B$2:$B$473,0)) -> Transport Services
A24: SE0005999836 | B24: 216 | C24: 8711 | D24: 1542 | E24: 3822 | F24: =INDEX(Industries!$D$2:$D$473,MATCH(B24,Industries!$B$2:$B$473,0)) -> Eng. & Contract Svs
A25: BE0974264930 | B25: 106 | C25: 6411 | D25: 6311 | E25: 6331 | F25: =INDEX(Industries!$D$2:$D$473,MATCH(B25,Industries!$B$2:$B$473,0)) -> Life Insurance
A26: NL0011794037 | B26: 88 | C26: 5411 | F26: =INDEX(Industries!$D$2:$D$473,MATCH(B26,Industries!$B$2:$B$473,0)) -> Food Retail & Wsale
A27: FR0000120073 | B27: 33 | C27: 2813 | D27: 5169 | E27: 8711 | F27: =INDEX(Industries!$D$2:$D$473,MATCH(B27,Industries!$B$2:$B$473,0)) -> Specialty Chemicals
A28: NL0000235190 | B28: 98 | C28: 3721 | D28: 3728 | E28: 3761 | F28: =INDEX(Industries!$D$2:$D$473,MATCH(B28,Industries!$B$2:$B$473,0)) -> Aerospace
A29: NO0010345853 | B29: 50 | C29: 1311 | D29: 1389 | F29: =INDEX(Industries!$D$2:$D$473,MATCH(B29,Industries!$B$2:$B$473,0)) -> Oil: Crude Producers
A30: NL0013267909 | B30: 33 | C30: 2851 | D30: 2821 | F30: =INDEX(Industries!$D$2:$D$473,MATCH(B30,Industries!$B$2:$B$473,0)) -> Specialty Chemicals
A31: CH0432492467 | B31: 103 | C31: 3589 | D31: 3841 | E31: 3851 | F31: =INDEX(Industries!$D$2:$D$473,MATCH(B31,Industries!$B$2:$B$473,0)) -> Medical Supplies
A32: SE0000695876 | B32: 213 | C32: 3585 | F32: =INDEX(Industries!$D$2:$D$473,MATCH(B32,Industries!$B$2:$B$473,0)) -> Elec. Eq: Control
A33: LU2237380790 | B33: 156 | C33: 5999 | F33: =INDEX(Industries!$D$2:$D$473,MATCH(B33,Industries!$B$2:$B$473,0)) -> Consumer Svs: Misc.
A34: DE0008404005 | B34: 141 | C34: 6311 | D34: 6324 | E34: 6331 | F34: =INDEX(Industries!$D$2:$D$473,MATCH(B34,Industries!$B$2:$B$473,0)) -> Full Line Insurance
A35: CH0008837566 | B35: 112 | C35: 1542 | D35: 1531 | E35: 6531 | F35: =INDEX(Industries!$D$2:$D$473,MATCH(B35,Industries!$B$2:$B$473,0)) -> Real Estate Hold, Dev
A36: FR0010220475 | B36: 258 | C36: 3743 | D36: 3711 | E36: 1629 | F36: =INDEX(Industries!$D$2:$D$473,MATCH(B36,Industries!$B$2:$B$473,0)) -> Electrical Components
A37: DE000A0LD2U1 | B37: 239 | C37: 6512 | D37: 6531 | F37: =INDEX(Industries!$D$2:$D$473,MATCH(B37,Industries!$B$2:$B$473,0)) -> Office REITs
A38: FR0000071946 | B38: 150 | C38: 7373 | F38: =INDEX(Industries!$D$2:$D$473,MATCH(B38,Industries!$B$2:$B$473,0)) -> Computer Services
A39: ES0109067019 | B39: 150 | C39: 7373 | D39: 7371 | E39: 7376 | F39: =INDEX(Industries!$D$2:$D$473,MATCH(B39,Industries!$B$2:$B$473,0)) -> Computer Services
A40: DK0060946788 | B40: 132 | C40: 3841 | D40: 3842 | F40: =INDEX(Industries!$D$2:$D$473,MATCH(B40,Industries!$B$2:$B$473,0)) -> Medical Equipment
...

Sheet Industries
A1: ICB Code | B1: INDG | C1: INDC | D1: INDM | E1: Datastream Sector Level
A2: 10 | B2: 183 | C2: TECNO | D2: Technology | E2: 2
A3: 1010 | B3: 183 | C3: TECNO | D3: Technology | E3: 3
A4: 101010 | B4: 176 | C4: SFTCS | D4: Software & Comp. Svs. | E4: 4
A5: 10101010 | B5: 150 | C5: CMPSV | D5: Computer Services | E5: 5
B6: 150 | C6: CMPSV | D6: Computer Services | E6: 6
A7: 10101015 | B7: 58 | C7: SOFTW | D7: Software | E7: 5
B8: 58 | C8: SOFTW | D8: Software | E8: 6
A9: 10101020 | B9: 151 | C9: CODGT | D9: Consumer Digital Svs | E9: 5
B10: 151 | C10: CODGT | D10: Consumer Digital Svs | E10: 6
A11: 101020 | B11: 175 | C11: TECHD | D11: Tech. Hardware, Equip | E11: 4
A12: 10102010 | B12: 130 | C12: SEMIC | D12: Semiconductors | E12: 5
B13: 130 | C13: SEMIC | D13: Semiconductors | E13: 6
A14: 10102015 | B14: 37 | C14: ELTCC | D14: Electronic Components | E14: 5
B15: 37 | C15: ELTCC | D15: Electronic Components | E15: 6
A16: 10102020 | B16: 245 | C16: PRDTE | D16: Prod. Tech. Equipment | E16: 5
B17: 245 | C17: PRDTE | D17: Prod. Tech. Equipment | E17: 6
A18: 10102030 | B18: 34 | C18: COMPH | D18: Computer Hardware | E18: 5
B19: 34 | C19: COMPH | D19: Computer Hardware | E19: 6
A20: 10102035 | B20: 105 | C20: OFFEQ | D20: Electronic Office Eq. | E20: 5
B21: 105 | C21: OFFEQ | D21: Electronic Office Eq. | E21: 6
A22: 15 | B22: 174 | C22: TELCM | D22: Telecommunications | E22: 2
A23: 1510 | B23: 174 | C23: TELCM | D23: Telecommunications | E23: 3
A24: 151010 | B24: 126 | C24: TELEQ | D24: Telecom. Equipment | E24: 4
A25: 15101010 | B25: 126 | C25: TELEQ | D25: Telecom. Equipment | E25: 5
B26: 126 | C26: TELEQ | D26: Telecom. Equipment | E26: 6
A27: 151020 | B27: 202 | C27: TELSP | D27: Telecom. Svs. Prvds. | E27: 4
A28: 15102010 | B28: 257 | C28: CABTV | D28: Cable TV Services | E28: 5
B29: 257 | C29: CABTV | D29: Cable TV Services | E29: 6
A30: 15102015 | B30: 142 | C30: TELSV | D30: Telecom. Services | E30: 5
B31: 142 | C31: TELSV | D31: Telecom. Services | E31: 6
A32: 20 | B32: 181 | C32: HLTHC | D32: Health Care | E32: 2
A33: 2010 | B33: 181 | C33: HLTHC | D33: Health Care | E33: 3
A34: 201010 | B34: 17 | C34: HLTPR | D34: Health Care Providers | E34: 4
A35: 20101010 | B35: 45 | C35: HCFAC | D35: Health Care Facility | E35: 5
B36: 45 | C36: HCFAC | D36: Health Care Facility | E36: 6
A37: 20101020 | B37: 221 | C37: HLTMS | D37: Health Care Mgmt. Svs | E37: 5
B38: 221 | C38: HLTMS | D38: Health Care Mgmt. Svs | E38: 6
A39: 20101025 | B39: 223 | C39: HLTSV | D39: Health Care Services | E39: 5
B40: 223 | C40: HLTSV | D40: Health Care Services | E40: 6
...
